Workbook

Sheet 1-1_Acceleration
A1: folder | B1: angle | C1: P195_UX_extreme | D1: P195_UY_extreme | E1: P195_range_2D_extreme | F1: P54000062_UX_extreme | G1: P54000062_UY_extreme | H1: P54000062_range_2D_extreme | I1: P54000070_UX_extreme | J1: P54000070_UY_extreme | K1: P54000070_range_2D_extreme | L1: P54000071_UX_extreme | M1: P54000071_UY_extreme | N1: P54000071_range_2D_extreme | O1: P54000079_UX_extreme | P1: P54000079_UY_extreme | Q1: P54000079_range_2D_extreme
A2: Model2_10yr_000 | B2: 0 | C2: 0.13789 | D2: 0.09133 | E2: 0.13786 | F2: 0.1445 | G2: 0.09846 | H2: 0.1451 | I2: 0.1445 | J2: 0.08956 | K2: 0.14459 | L2: 0.13569 | M2: 0.09846 | N2: 0.13567 | O2: 0.13569 | P2: 0.08956 | Q2: 0.13583
A3: Model2_10yr_005 | B3: 5 | C3: 0.06455 | D3: 0.1382 | E3: 0.13821 | F3: 0.06993 | G3: 0.14532 | H3: 0.14553 | I3: 0.06993 | J3: 0.13382 | K3: 0.13381 | L3: 0.06513 | M3: 0.14532 | N3: 0.14563 | O3: 0.06513 | P3: 0.13382 | Q3: 0.13409
A4: Model2_10yr_010 | B4: 10 | C4: 0.05431 | D4: 0.12631 | E4: 0.1263 | F4: 0.05964 | G4: 0.13277 | H4: 0.13299 | I4: 0.05964 | J4: 0.12255 | K4: 0.12254 | L4: 0.05525 | M4: 0.13277 | N4: 0.13301 | O4: 0.05525 | P4: 0.12255 | Q4: 0.12271
A5: Model2_10yr_015 | B5: 15 | C5: 0.05923 | D5: 0.11303 | E5: 0.11305 | F5: 0.06428 | G5: 0.11871 | H5: 0.11886 | I5: 0.06428 | J5: 0.11024 | K5: 0.11024 | L5: 0.06012 | M5: 0.11871 | N5: 0.11905 | O5: 0.06012 | P5: 0.11024 | Q5: 0.1105
A6: Model2_10yr_020 | B6: 20 | C6: 0.04992 | D6: 0.09479 | E6: 0.09488 | F6: 0.05414 | G6: 0.09951 | H6: 0.09955 | I6: 0.05414 | J6: 0.09245 | K6: 0.0925 | L6: 0.05038 | M6: 0.09951 | N6: 0.09992 | O6: 0.05038 | P6: 0.09245 | Q6: 0.0928
A7: Model2_10yr_025 | B7: 25 | C7: 0.05089 | D7: 0.07772 | E7: 0.07779 | F7: 0.05461 | G7: 0.08182 | H7: 0.08194 | I7: 0.05461 | J7: 0.07587 | K7: 0.07595 | L7: 0.05129 | M7: 0.08182 | N7: 0.08219 | O7: 0.05129 | P7: 0.07587 | Q7: 0.07624
A8: Model2_10yr_030 | B8: 30 | C8: 0.05011 | D8: 0.07793 | E8: 0.07796 | F8: 0.05331 | G8: 0.08202 | H8: 0.08217 | I8: 0.05331 | J8: 0.0757 | K8: 0.07571 | L8: 0.05036 | M8: 0.08202 | N8: 0.08229 | O8: 0.05036 | P8: 0.0757 | Q8: 0.07599
A9: Model2_10yr_035 | B9: 35 | C9: 0.0563 | D9: 0.06966 | E9: 0.07165 | F9: 0.05936 | G9: 0.07321 | H9: 0.0754 | I9: 0.05936 | J9: 0.06785 | K9: 0.07212 | L9: 0.05588 | M9: 0.07321 | N9: 0.07381 | O9: 0.05588 | P9: 0.06785 | Q9: 0.07032
A10: Model2_10yr_040 | B10: 40 | C10: 0.05612 | D10: 0.06205 | E10: 0.06691 | F10: 0.05919 | G10: 0.06571 | H10: 0.07073 | I10: 0.05919 | J10: 0.06001 | K10: 0.06742 | L10: 0.05525 | M10: 0.06571 | N10: 0.06866 | O10: 0.05525 | P10: 0.06001 | Q10: 0.06524
A11: Model2_10yr_045 | B11: 45 | C11: 0.0541 | D11: 0.06194 | E11: 0.06579 | F11: 0.05694 | G11: 0.06537 | H11: 0.06934 | I11: 0.05694 | J11: 0.05989 | K11: 0.0661 | L11: 0.05318 | M11: 0.06537 | N11: 0.06741 | O11: 0.05318 | P11: 0.05989 | Q11: 0.06407
A13: P54000071_UX_extreme | B13: P54000071_UY_extreme | C13: P54000071_range_2D_extreme
A14: 0.13569 | B14: 0.09846 | C14: 0.13567
A15: 0.06513 | B15: 0.14532 | C15: 0.14563
A16: 0.05525 | B16: 0.13277 | C16: 0.13301
A17: 0.06012 | B17: 0.11871 | C17: 0.11905
A18: 0.05038 | B18: 0.09951 | C18: 0.09992
A19: 0.05129 | B19: 0.08182 | C19: 0.08219
A20: 0.05036 | B20: 0.08202 | C20: 0.08229
A21: 0.05588 | B21: 0.07321 | C21: 0.07381
A22: 0.05525 | B22: 0.06571 | C22: 0.06866
A23: 0.05318 | B23: 0.06537 | C23: 0.06741

Sheet 2-1_Acceleration
A1: folder | B1: angle | C1: P285_UX_extreme | D1: P285_UY_extreme | E1: P285_range_2D_extreme | F1: P54000047_UX_extreme | G1: P54000047_UY_extreme | H1: P54000047_range_2D_extreme | I1: P54000050_UX_extreme | J1: P54000050_UY_extreme | K1: P54000050_range_2D_extreme | L1: P54000059_UX_extreme | M1: P54000059_UY_extreme | N1: P54000059_range_2D_extreme | O1: P54000058_UX_extreme | P1: P54000058_UY_extreme | Q1: P54000058_range_2D_extreme
A2: Model3_10yr_000 | B2: 0 | C2: 0.0804 | D2: 0.05933 | E2: 0.08038 | F2: 0.07439 | G2: 0.05649 | H2: 0.07686 | I2: 0.08714 | J2: 0.05649 | K2: 0.08851 | L2: 0.08714 | M2: 0.06988 | N2: 0.09107 | O2: 0.07439 | P2: 0.06988 | Q2: 0.08165
A3: Model3_10yr_005 | B3: 5 | C3: 0.06807 | D3: 0.0604 | E3: 0.0728 | F3: 0.06318 | G3: 0.05726 | H3: 0.06821 | I3: 0.07382 | J3: 0.05726 | K3: 0.07608 | L3: 0.07382 | M3: 0.06989 | N3: 0.08132 | O3: 0.06318 | P3: 0.06989 | Q3: 0.07537
A4: Model3_10yr_010 | B4: 10 | C4: 0.08329 | D4: 0.06084 | E4: 0.08329 | F4: 0.07714 | G4: 0.05746 | H4: 0.08007 | I4: 0.09003 | J4: 0.05746 | K4: 0.09157 | L4: 0.09003 | M4: 0.07117 | N4: 0.09331 | O4: 0.07714 | P4: 0.07117 | Q4: 0.08395
A5: Model3_10yr_015 | B5: 15 | C5: 0.06772 | D5: 0.05827 | E5: 0.07147 | F5: 0.06274 | G5: 0.05482 | H5: 0.06664 | I5: 0.07332 | J5: 0.05482 | K5: 0.07473 | L5: 0.07332 | M5: 0.06708 | N5: 0.07949 | O5: 0.06274 | P5: 0.06708 | Q5: 0.07347
A6: Model3_10yr_020 | B6: 20 | C6: 0.07282 | D6: 0.05471 | E6: 0.07295 | F6: 0.06737 | G6: 0.05319 | H6: 0.07097 | I6: 0.07887 | J6: 0.05319 | K6: 0.08101 | L6: 0.07887 | M6: 0.06287 | N6: 0.08122 | O6: 0.06737 | P6: 0.06287 | Q6: 0.07371
A7: Model3_10yr_025 | B7: 25 | C7: 0.05991 | D7: 0.04971 | E7: 0.06227 | F7: 0.05564 | G7: 0.04763 | H7: 0.05859 | I7: 0.0649 | J7: 0.04763 | K7: 0.0661 | L7: 0.0649 | M7: 0.05754 | N7: 0.06938 | O7: 0.05564 | P7: 0.05754 | Q7: 0.06403
A8: Model3_10yr_030 | B8: 30 | C8: 0.05742 | D8: 0.04465 | E8: 0.05819 | F8: 0.05314 | G8: 0.04254 | H8: 0.05497 | I8: 0.06227 | J8: 0.04254 | K8: 0.06321 | L8: 0.06227 | M8: 0.05214 | N8: 0.06577 | O8: 0.05314 | P8: 0.05214 | Q8: 0.05955
A9: Model3_10yr_035 | B9: 35 | C9: 0.05216 | D9: 0.03394 | E9: 0.05217 | F9: 0.04826 | G9: 0.03413 | H9: 0.04976 | I9: 0.05651 | J9: 0.03413 | K9: 0.05767 | L9: 0.05651 | M9: 0.03941 | N9: 0.05808 | O9: 0.04826 | P9: 0.03941 | Q9: 0.04984
A10: Model3_10yr_040 | B10: 40 | C10: 0.04846 | D10: 0.03325 | E10: 0.04848 | F10: 0.0448 | G10: 0.03268 | H10: 0.04655 | I10: 0.05247 | J10: 0.03268 | K10: 0.05363 | L10: 0.05247 | M10: 0.03849 | N10: 0.0539 | O10: 0.0448 | P10: 0.03849 | Q10: 0.04725
A11: Model3_10yr_045 | B11: 45 | C11: 0.04989 | D11: 0.03177 | E11: 0.04994 | F11: 0.04615 | G11: 0.03204 | H11: 0.04788 | I11: 0.054 | J11: 0.03204 | K11: 0.05533 | L11: 0.054 | M11: 0.03678 | N11: 0.0551 | O11: 0.04615 | P11: 0.03678 | Q11: 0.04721
A12: Model3_10yr_050 | B12: 50 | C12: 0.05655 | D12: 0.02769 | E12: 0.05668 | F12: 0.05221 | G12: 0.02984 | H12: 0.0541 | I12: 0.0611 | J12: 0.02984 | K12: 0.06273 | L12: 0.0611 | M12: 0.03172 | N12: 0.06164 | O12: 0.05221 | P12: 0.03172 | Q12: 0.05249
A13: Model3_10yr_055 | B13: 55 | C13: 0.05917 | D13: 0.02699 | E13: 0.0592 | F13: 0.05447 | G13: 0.02869 | H13: 0.056 | I13: 0.06404 | J13: 0.02869 | K13: 0.06534 | L13: 0.06404 | M13: 0.03195 | N13: 0.0649 | O13: 0.05447 | P13: 0.03195 | Q13: 0.05505
... A20: Model3_10yr_090 | B20: 90 | C20: 0.08461 | D20: 0.03758 | E20: 0.08462 | F20: 0.0782 | G20: 0.03981 | H20: 0.07993 | I20: 0.09127 | J20: 0.03981 | K20: 0.09279 | L20: 0.09127 | M20: 0.04465 | N20: 0.0925 | O20: 0.0782 | P20: 0.04465 | Q20: 0.07901
A22: P54000059_UX_extreme | B22: P54000059_UY_extreme | C22: P54000059_range_2D_extreme
A23: 0.08714 | B23: 0.06988 | C23: 0.09107
A24: 0.07382 | B24: 0.06989 | C24: 0.08132
A25: 0.09003 | B25: 0.07117 | C25: 0.09331
A26: 0.07332 | B26: 0.06708 | C26: 0.07949
A27: 0.07887 | B27: 0.06287 | C27: 0.08122
A28: 0.0649 | B28: 0.05754 | C28: 0.06938
A29: 0.06227 | B29: 0.05214 | C29: 0.06577
A30: 0.05651 | B30: 0.03941 | C30: 0.05808
A31: 0.05247 | B31: 0.03849 | C31: 0.0539
A32: 0.054 | B32: 0.03678 | C32: 0.0551
A33: 0.0611 | B33: 0.03172 | C33: 0.06164
A34: 0.06404 | B34: 0.03195 | C34: 0.0649
... A41: 0.09127 | B41: 0.04465 | C41: 0.0925

Sheet 3-1_Acceleration
A1: folder | B1: angle | C1: P378_UX_extreme | D1: P378_UY_extreme | E1: P378_range_2D_extreme | F1: P54000060_UX_extreme | G1: P54000060_UY_extreme | H1: P54000060_range_2D_extreme | I1: P54000059_UX_extreme | J1: P54000059_UY_extreme | K1: P54000059_range_2D_extreme | L1: P54000066_UX_extreme | M1: P54000066_UY_extreme | N1: P54000066_range_2D_extreme | O1: P54000067_UX_extreme | P1: P54000067_UY_extreme | Q1: P54000067_range_2D_extreme
A2: Model4_10yr_000 | B2: 0 | C2: 0.06698 | D2: 0.03353 | E2: 0.06697 | F2: 0.06779 | G2: 0.02919 | H2: 0.06779 | I2: 0.06644 | J2: 0.02919 | K2: 0.06646 | L2: 0.06644 | M2: 0.0425 | N2: 0.06643 | O2: 0.06779 | P2: 0.0425 | Q2: 0.06803
A3: Model4_10yr_005 | B3: 5 | C3: 0.06431 | D3: 0.03577 | E3: 0.06431 | F3: 0.06513 | G3: 0.02974 | H3: 0.06513 | I3: 0.06376 | J3: 0.02974 | K3: 0.0638 | L3: 0.06376 | M3: 0.04542 | N3: 0.06376 | O3: 0.06513 | P3: 0.04542 | Q3: 0.06552
A4: Model4_10yr_010 | B4: 10 | C4: 0.0639 | D4: 0.03572 | E4: 0.0639 | F4: 0.06472 | G4: 0.03046 | H4: 0.06475 | I4: 0.06335 | J4: 0.03046 | K4: 0.06345 | L4: 0.06335 | M4: 0.04479 | N4: 0.06335 | O4: 0.06472 | P4: 0.04479 | Q4: 0.06491
A5: Model4_10yr_015 | B5: 15 | C5: 0.06464 | D5: 0.03647 | E5: 0.06464 | F5: 0.06541 | G5: 0.03109 | H5: 0.06544 | I5: 0.06418 | J5: 0.03109 | K5: 0.06426 | L5: 0.06418 | M5: 0.04604 | N5: 0.06419 | O5: 0.06541 | P5: 0.04604 | Q5: 0.06562
A6: Model4_10yr_020 | B6: 20 | C6: 0.06015 | D6: 0.03686 | E6: 0.06017 | F6: 0.0609 | G6: 0.03155 | H6: 0.06096 | I6: 0.05978 | J6: 0.03155 | K6: 0.05992 | L6: 0.05978 | M6: 0.04671 | N6: 0.06069 | O6: 0.0609 | P6: 0.04671 | Q6: 0.0614
A7: Model4_10yr_025 | B7: 25 | C7: 0.04651 | D7: 0.03164 | E7: 0.04651 | F7: 0.04724 | G7: 0.02724 | H7: 0.04724 | I7: 0.04614 | J7: 0.02724 | K7: 0.04618 | L7: 0.04614 | M7: 0.04033 | N7: 0.04902 | O7: 0.04724 | P7: 0.04033 | Q7: 0.04969
A8: Model4_10yr_030 | B8: 30 | C8: 0.04694 | D8: 0.02645 | E8: 0.04694 | F8: 0.04749 | G8: 0.02298 | H8: 0.0475 | I8: 0.04668 | J8: 0.02298 | K8: 0.04672 | L8: 0.04668 | M8: 0.03352 | N8: 0.04669 | O8: 0.04749 | P8: 0.03352 | Q8: 0.04766
A9: Model4_10yr_035 | B9: 35 | C9: 0.04476 | D9: 0.02312 | E9: 0.04476 | F9: 0.04527 | G9: 0.01995 | H9: 0.04528 | I9: 0.0445 | J9: 0.01995 | K9: 0.04452 | L9: 0.0445 | M9: 0.0296 | N9: 0.0445 | O9: 0.04527 | P9: 0.0296 | Q9: 0.04544
A10: Model4_10yr_040 | B10: 40 | C10: 0.04523 | D10: 0.01974 | E10: 0.04522 | F10: 0.04577 | G10: 0.01737 | H10: 0.04579 | I10: 0.04486 | J10: 0.01737 | K10: 0.04489 | L10: 0.04486 | M10: 0.02512 | N10: 0.04485 | O10: 0.04577 | P10: 0.02512 | Q10: 0.04584
A11: Model4_10yr_045 | B11: 45 | C11: 0.04985 | D11: 0.01913 | E11: 0.04985 | F11: 0.05042 | G11: 0.01653 | H11: 0.05043 | I11: 0.04941 | J11: 0.01653 | K11: 0.04944 | L11: 0.04941 | M11: 0.02417 | N11: 0.04943 | O11: 0.05042 | P11: 0.02417 | Q11: 0.0505
A12: Model4_10yr_050 | B12: 50 | C12: 0.04362 | D12: 0.01741 | E12: 0.04362 | F12: 0.0441 | G12: 0.01505 | H12: 0.04412 | I12: 0.04325 | J12: 0.01505 | K12: 0.04328 | L12: 0.04325 | M12: 0.02213 | N12: 0.04325 | O12: 0.0441 | P12: 0.02213 | Q12: 0.04415
A13: Model4_10yr_055 | B13: 55 | C13: 0.04395 | D13: 0.01648 | E13: 0.04395 | F13: 0.04442 | G13: 0.01433 | H13: 0.04446 | I13: 0.04358 | J13: 0.01433 | K13: 0.04363 | L13: 0.04358 | M13: 0.02075 | N13: 0.04357 | O13: 0.04442 | P13: 0.02075 | Q13: 0.04443
... A20: Model4_10yr_090 | B20: 90 | C20: 0.07323 | D20: 0.01932 | E20: 0.07323 | F20: 0.07409 | G20: 0.01697 | H20: 0.07411 | I20: 0.07244 | J20: 0.01697 | K20: 0.07246 | L20: 0.07244 | M20: 0.02484 | N20: 0.07248 | O20: 0.07409 | P20: 0.02484 | Q20: 0.07419
A22: P54000067_UX_extreme | B22: P54000067_UY_extreme | C22: P54000067_range_2D_extreme
A23: 0.06779 | B23: 0.0425 | C23: 0.06803
A24: 0.06513 | B24: 0.04542 | C24: 0.06552
A25: 0.06472 | B25: 0.04479 | C25: 0.06491
A26: 0.06541 | B26: 0.04604 | C26: 0.06562
A27: 0.0609 | B27: 0.04671 | C27: 0.0614
A28: 0.04724 | B28: 0.04033 | C28: 0.04969
A29: 0.04749 | B29: 0.03352 | C29: 0.04766
A30: 0.04527 | B30: 0.0296 | C30: 0.04544
A31: 0.04577 | B31: 0.02512 | C31: 0.04584
A32: 0.05042 | B32: 0.02417 | C32: 0.0505
A33: 0.0441 | B33: 0.02213 | C33: 0.04415
A34: 0.04442 | B34: 0.02075 | C34: 0.04443
... A41: 0.07409 | B41: 0.02484 | C41: 0.07419

Sheet 结果对比
A1: 图18(a)
A2: 1-1模型
A3: matlab | B3: 集中质量模型 | E3: SAP2000模型 | H3: 偏差(%)
A4: 角度 | B4: X | C4: Y | D4: A | E4: X | F4: Y | G4: A | H4: X | I4: Y | J4: A
A5: 0 | B5: 0.14461754 | C5: 0.22422938 | D5: 0.22881802 | E5: ='1-1_Acceleration'!A14 | F5: ='1-1_Acceleration'!B14 | G5: ='1-1_Acceleration'!C14 | H5: =(E5-B5)/B5 | I5: =(F5-C5)/C5 | J5: =(G5-D5)/D5
A6: 0.087266463 | B6: 0.14574383 | C6: 0.23891485 | D6: 0.24201859 | E6: ='1-1_Acceleration'!A15 | F6: ='1-1_Acceleration'!B15 | G6: ='1-1_Acceleration'!C15 | H6: =(E6-B6)/B6 | I6: =(F6-C6)/C6 | J6: =(G6-D6)/D6
A7: 0.17453293 | B7: 0.12321832 | C7: 0.19555042 | D7: 0.19790103 | E7: ='1-1_Acceleration'!A16 | F7: ='1-1_Acceleration'!B16 | G7: ='1-1_Acceleration'!C16 | H7: =(E7-B7)/B7 | I7: =(F7-C7)/C7 | J7: =(G7-D7)/D7
A8: 0.26179939 | B8: 0.11919093 | C8: 0.19996638 | D8: 0.20128748 | E8: ='1-1_Acceleration'!A17 | F8: ='1-1_Acceleration'!B17 | G8: ='1-1_Acceleration'!C17 | H8: =(E8-B8)/B8 | I8: =(F8-C8)/C8 | J8: =(G8-D8)/D8
A9: 0.34906585 | B9: 0.10574055 | C9: 0.14722937 | D9: 0.15036555 | E9: ='1-1_Acceleration'!A18 | F9: ='1-1_Acceleration'!B18 | G9: ='1-1_Acceleration'!C18 | H9: =(E9-B9)/B9 | I9: =(F9-C9)/C9 | J9: =(G9-D9)/D9
A10: 0.43633231 | B10: 0.11315133 | C10: 0.11653426 | D10: 0.12994388 | E10: ='1-1_Acceleration'!A19 | F10: ='1-1_Acceleration'!B19 | G10: ='1-1_Acceleration'!C19 | H10: =(E10-B10)/B10 | I10: =(F10-C10)/C10 | J10: =(G10-D10)/D10
A11: 0.52359878 | B11: 0.10481181 | C11: 0.12734449 | D11: 0.13194456 | E11: ='1-1_Acceleration'!A20 | F11: ='1-1_Acceleration'!B20 | G11: ='1-1_Acceleration'!C20 | H11: =(E11-B11)/B11 | I11: =(F11-C11)/C11 | J11: =(G11-D11)/D11
A12: 0.61086524 | B12: 0.11044657 | C12: 0.11441571 | D12: 0.12722113 | E12: ='1-1_Acceleration'!A21 | F12: ='1-1_Acceleration'!B21 | G12: ='1-1_Acceleration'!C21 | H12: =(E12-B12)/B12 | I12: =(F12-C12)/C12 | J12: =(G12-D12)/D12
A13: 0.6981317 | B13: 0.10275249 | C13: 0.096404404 | D13: 0.11271737 | E13: ='1-1_Acceleration'!A22 | F13: ='1-1_Acceleration'!B22 | G13: ='1-1_Acceleration'!C22 | H13: =(E13-B13)/B13 | I13: =(F13-C13)/C13 | J13: =(G13-D13)/D13
A14: 0.78539816 | B14: 0.097253659 | C14: 0.10631357 | D14: 0.11526901 | E14: ='1-1_Acceleration'!A23 | F14: ='1-1_Acceleration'!B23 | G14: ='1-1_Acceleration'!C23 | H14: =(E14-B14)/B14 | I14: =(F14-C14)/C14 | J14: =(G14-D14)/D14
A15: 0.87266463 | B15: 0.096404404 | C15: 0.10275249 | D15: 0.11271737
A16: 0.95993109 | B16: 0.11441571 | C16: 0.11044657 | D16: 0.12722113
A17: 1.0471976 | B17: 0.12734449 | C17: 0.10481181 | D17: 0.13194456
A18: 1.134464 | B18: 0.11653426 | C18: 0.11315133 | D18: 0.12994388
A19: 1.2217305 | B19: 0.14722937 | C19: 0.10574055 | D19: 0.15036555
A20: 1.3089969 | B20: 0.19996638 | C20: 0.11919093 | D20: 0.20128748
A21: 1.3962634 | B21: 0.19555042 | C21: 0.12321832 | D21: 0.19790103
A22: 1.4835299 | B22: 0.23891485 | C22: 0.14574383 | D22: 0.24201859
A23: 1.5707963 | B23: 0.22422938 | C23: 0.14461754 | D23: 0.22881802
A27: 2-1模型
A28: matlab | B28: 集中质量模型 | E28: SAP2000模型 | H28: 偏差(%)
A29: 角度 | B29: X | C29: Y | D29: A | E29: X | F29: Y | G29: A | H29: X | I29: Y | J29: A
A30: 0 | B30: 0.13223209 | C30: 0.095521893 | D30: 0.13761964 | E30: ='2-1_Acceleration'!A23 | F30: ='2-1_Acceleration'!B23 | G30: ='2-1_Acceleration'!C23 | H30: =(E30-B30)/B30 | I30: =(F30-C30)/C30 | J30: =(G30-D30)/D30
A31: 0.087266463 | B31: 0.12168387 | C31: 0.097854451 | D31: 0.12609627 | E31: ='2-1_Acceleration'!A24 | F31: ='2-1_Acceleration'!B24 | G31: ='2-1_Acceleration'!C24 | H31: =(E31-B31)/B31 | I31: =(F31-C31)/C31 | J31: =(G31-D31)/D31
A32: 0.17453293 | B32: 0.12946931 | C32: 0.09811968 | D32: 0.13483158 | E32: ='2-1_Acceleration'!A25 | F32: ='2-1_Acceleration'!B25 | G32: ='2-1_Acceleration'!C25 | H32: =(E32-B32)/B32 | I32: =(F32-C32)/C32 | J32: =(G32-D32)/D32
A33: 0.26179939 | B33: 0.11992764 | C33: 0.090768805 | D33: 0.12538389 | E33: ='2-1_Acceleration'!A26 | F33: ='2-1_Acceleration'!B26 | G33: ='2-1_Acceleration'!C26 | H33: =(E33-B33)/B33 | I33: =(F33-C33)/C33 | J33: =(G33-D33)/D33
A34: 0.34906585 | B34: 0.12460646 | C34: 0.092318128 | D34: 0.12927704 | E34: ='2-1_Acceleration'!A27 | F34: ='2-1_Acceleration'!B27 | G34: ='2-1_Acceleration'!C27 | H34: =(E34-B34)/B34 | I34: =(F34-C34)/C34 | J34: =(G34-D34)/D34
A35: 0.43633231 | B35: 0.1042117 | C35: 0.071819293 | D35: 0.10787189 | E35: ='2-1_Acceleration'!A28 | F35: ='2-1_Acceleration'!B28 | G35: ='2-1_Acceleration'!C28 | H35: =(E35-B35)/B35 | I35: =(F35-C35)/C35 | J35: =(G35-D35)/D35
A36: 0.52359878 | B36: 0.096632271 | C36: 0.066401017 | D36: 0.099507069 | E36: ='2-1_Acceleration'!A29 | F36: ='2-1_Acceleration'!B29 | G36: ='2-1_Acceleration'!C29 | H36: =(E36-B36)/B36 | I36: =(F36-C36)/C36 | J36: =(G36-D36)/D36
A37: 0.61086524 | B37: 0.096736048 | C37: 0.058162268 | D37: 0.098793607 | E37: ='2-1_Acceleration'!A30 | F37: ='2-1_Acceleration'!B30 | G37: ='2-1_Acceleration'!C30 | H37: =(E37-B37)/B37 | I37: =(F37-C37)/C37 | J37: =(G37-D37)/D37
A38: 0.6981317 | B38: 0.0833724 | C38: 0.056316041 | D38: 0.086108604 | E38: ='2-1_Acceleration'!A31 | F38: ='2-1_Acceleration'!B31 | G38: ='2-1_Acceleration'!C31 | H38: =(E38-B38)/B38 | I38: =(F38-C38)/C38 | J38: =(G38-D38)/D38
A39: 0.78539816 | B39: 0.082268566 | C39: 0.049343469 | D39: 0.084053221 | E39: ='2-1_Acceleration'!A32 | F39: ='2-1_Acceleration'!B32 | G39: ='2-1_Acceleration'!C32 | H39: =(E39-B39)/B39 | I39: =(F39-C39)/C39 | J39: =(G39-D39)/D39
A40: 0.87266463 | B40: 0.083951696 | C40: 0.055538906 | D40: 0.086621157 | E40: ='2-1_Acceleration'!A33 | F40: ='2-1_Acceleration'!B33 | G40: ='2-1_Acceleration'!C33 | H40: =(E40-B40)/B40 | I40: =(F40-C40)/C40 | J40: =(G40-D40)/D40
A41: 0.95993109 | B41: 0.088765076 | C41: 0.047363952 | D41: 0.090717792 | E41: ='2-1_Acceleration'!A34 | F41: ='2-1_Acceleration'!B34 | G41: ='2-1_Acceleration'!C34 | H41: =(E41-B41)/B41 | I41: =(F41-C41)/C41 | J41: =(G41-D41)/D41
... A48: 1.5707963 | B48: 0.16496814 | C48: 0.086099366 | D48: 0.17574629 | E48: ='2-1_Acceleration'!A41 | F48: ='2-1_Acceleration'!B41 | G48: ='2-1_Acceleration'!C41 | H48: =(E48-B48)/B48 | I48: =(F48-C48)/C48 | J48: =(G48-D48)/D48
A55: 3-1模型
...

Sheet Sheet2
A1: 200 | B1: 1830 | C1: 3792 | D1: =(C1-B1)/B1 | E1: 6.07 | F1: 6.809 | G1: =(F1-E1)/E1
A2: 196 | B2: 1830 | C2: 3792 | D2: =(C2-B2)/B2 | E2: 5.35 | F2: 5.66815 | G2: =(F2-E2)/E2
A3: 192 | B3: 565000 | C3: 2712900 | D3: =(C3-B3)/B3 | E3: 4.82 | F3: 5.159061 | G3: =(F3-E3)/E3
A4: 189 | B4: 1910 | C4: 3792 | D4: =(C4-B4)/B4 | E4: 1.96 | F4: 2.172484 | G4: =(F4-E4)/E4
A5: 185 | B5: 1910 | C5: 3792 | D5: =(C5-B5)/B5 | E5: 1.56 | F5: 1.656954 | G5: =(F5-E5)/E5
A6: ….
A7: 23.1 | B7: 2820
A8: 19.5 | B8: 799000
A9: 15 | B9: 2610
A10: 10.5 | B10: 2610
A11: 6 | B11: 664000
